Workbook

Sheet Database
A1: REFERENCECONTRAT_ | B1: COUNTRYRESIDENCECODE_ | C1: INSTITUTIONALSECTORCODE_ | D1: BIRTHDATE_ | E1: COMMUNENAISSANCECODE_ | F1: GENDAR_ | G1: NATIONALITYCODE_ | H1: PROFESSIONCODE_ | I1: RESIDENTTYPECODE_ | J1: CATEGORIEENGAGEMENTCODE_ | K1: ESTCREDITINTERNE_ | L1: FINANCIALINSTITUTIONCODE_ | M1: MATURITECODE_ | N1: MONTANT_ | Q1: PERIODICITE_ | R1: TAUXEFFECTIFGLOBAL_ | S1: TAUXINTERET_ | T1: TYPEAMORTISSEMENT_ | U1: TYPEENGAGEMENTCODE_ | V1: CLASSEACTUELLECODE_ | W1: Classe | X1: CRDU_ | Y1: FINANCIALINSTITUTIONCODE_.1 | Z1: MAXIMPAYE_ | AA1: NBRJOURSENDEFAUT_ | AB1: TOTALENCOURS_ | AC1: TOTALIMPAYE_ | AD1: TOTALPROVISION_ | AE1: jkhkhih
A2: 495646 | B2: MG | C2: 41 | D2: 1954-03-28 00:00:00 | F2: Female | G2: MG | H2: 521z | I2: 0 | J2: 2 | K2: 0 | L2: MG/00009 | M2: CourtTerme | N2: 1660328.9 | O2: =AC2 -> 1660328.9 | P2: =N2=O2 -> TRUE | Q2: Mensuelle | R2: 0 | S2: 21 | T2: Degressif | U2: F06B | V2: 01/03 | W2: =IF(VLOOKUP(V2,'reference classification'!$B$1:G6,6,FALSE)>90,1,0) -> 1 | X2: 0 | Y2: MG/00009 | Z2: 1660328.9 | AA2: 120 | AB2: 1660328.9 | AC2: 1660328.9 | AD2: 0 | AE2: =AB2=AC2 -> TRUE
A3: 539953 | B3: MG | C3: 41 | D3: 1981-06-10 00:00:00 | F3: Female | G3: MG | H3: 542z | I3: 0 | J3: 2 | K3: 0 | L3: MG/00009 | M3: CourtTerme | N3: 217527.34 | O3: =AC3 -> 217527.34 | P3: =N3=O3 -> TRUE | Q3: Mensuelle | R3: 0 | S3: 0 | T3: Degressif | U3: F06B | V3: 01/03 | W3: =IF(VLOOKUP(V3,'reference classification'!$B$1:G7,6,FALSE)>90,1,0) -> 1 | X3: 0 | Y3: MG/00009 | Z3: 217527.34 | AA3: 120 | AB3: 217527.34 | AC3: 217527.34 | AD3: 0 | AE3: =AB3=AC3 -> TRUE
A4: 551627 | B4: MG | C4: 41 | D4: 1983-05-07 00:00:00 | F4: Male | G4: MG | H4: 542z | I4: 0 | J4: 2 | K4: 0 | L4: MG/00009 | M4: CourtTerme | N4: 443219.86 | O4: =AC4 -> 443219.86 | P4: =N4=O4 -> TRUE | Q4: Mensuelle | R4: 0 | S4: 0 | T4: Degressif | U4: F06B | V4: 01/03 | W4: =IF(VLOOKUP(V4,'reference classification'!$B$1:G8,6,FALSE)>90,1,0) -> 1 | X4: 0 | Y4: MG/00009 | Z4: 443219.86 | AA4: 120 | AB4: 443219.86 | AC4: 443219.86 | AD4: 0 | AE4: =AB4=AC4 -> TRUE
A5: 736497 | B5: MG | C5: 41 | D5: 1962-01-01 00:00:00 | E5: 4223010 | F5: Male | G5: MG | H5: 542z | I5: 0 | J5: 2 | K5: 0 | L5: MG/00009 | M5: CourtTerme | N5: 265939.67 | O5: =AC5 -> 265939.67 | P5: =N5=O5 -> TRUE | Q5: Mensuelle | R5: 0 | S5: 21 | T5: Degressif | U5: F06B | V5: 01/03 | W5: =IF(VLOOKUP(V5,'reference classification'!$B$1:G9,6,FALSE)>90,1,0) -> 1 | X5: 0 | Y5: MG/00009 | Z5: 265939.67 | AA5: 120 | AB5: 265939.67 | AC5: 265939.67 | AD5: 0 | AE5: =AB5=AC5 -> TRUE
A6: 774022 | B6: MG | C6: 41 | D6: 1974-10-24 00:00:00 | F6: Male | G6: MG | H6: 542z | I6: 0 | J6: 1 | K6: 0 | L6: MG/00009 | M6: CourtTerme | N6: 260388 | O6: =AC6 -> 260388 | P6: =N6=O6 -> TRUE | Q6: Mensuelle | R6: 0 | S6: 0 | T6: Degressif | U6: F10B | V6: 01/03 | W6: =IF(VLOOKUP(V6,'reference classification'!$B$1:G10,6,FALSE)>90,1,0) -> 1 | X6: 0 | Y6: MG/00009 | Z6: 260388 | AA6: 118 | AB6: 260388 | AC6: 260388 | AD6: 0 | AE6: =AB6=AC6 -> TRUE
A7: 980501 | B7: MG | C7: 41 | D7: 1967-03-26 00:00:00 | F7: Male | G7: MG | H7: 542z | I7: 0 | J7: 2 | K7: 0 | L7: MG/00009 | M7: CourtTerme | N7: 14400 | O7: =AC7 -> 14400 | P7: =N7=O7 -> TRUE | Q7: Mensuelle | R7: 0 | S7: 21 | T7: Degressif | U7: F06B | V7: 01/03 | W7: =IF(VLOOKUP(V7,'reference classification'!$B$1:G11,6,FALSE)>90,1,0) -> 1 | X7: 0 | Y7: MG/00009 | Z7: 14400 | AA7: 120 | AB7: 14400 | AC7: 14400 | AD7: 0 | AE7: =AB7=AC7 -> TRUE
A8: 1000357 | B8: MG | C8: 41 | D8: 1967-03-26 00:00:00 | F8: Male | G8: MG | H8: 542z | I8: 0 | J8: 1 | K8: 0 | L8: MG/00009 | M8: CourtTerme | N8: 737940 | O8: =AC8 -> 737940 | P8: =N8=O8 -> TRUE | Q8: Mensuelle | R8: 0 | S8: 0 | T8: Degressif | U8: F10B | V8: 01/03 | W8: =IF(VLOOKUP(V8,'reference classification'!$B$1:G12,6,FALSE)>90,1,0) -> 1 | X8: 0 | Y8: MG/00009 | Z8: 737940 | AA8: 118 | AB8: 737940 | AC8: 737940 | AD8: 0 | AE8: =AB8=AC8 -> TRUE
A9: 1087673 | B9: MG | C9: 41 | D9: 1979-08-21 00:00:00 | F9: Male | G9: MG | H9: 542z | I9: 0 | J9: 2 | K9: 0 | L9: MG/00009 | M9: CourtTerme | N9: 9597.91 | O9: =AC9 -> 9597.91 | P9: =N9=O9 -> TRUE | Q9: Mensuelle | R9: 0 | S9: 21 | T9: Degressif | U9: F06B | V9: 01/03 | W9: =IF(VLOOKUP(V9,'reference classification'!$B$1:G13,6,FALSE)>90,1,0) -> 1 | X9: 0 | Y9: MG/00009 | Z9: 9597.91 | AA9: 120 | AB9: 9597.91 | AC9: 9597.91 | AD9: 0 | AE9: =AB9=AC9 -> TRUE
A10: 1112872 | B10: MG | C10: 41 | D10: 1972-09-22 00:00:00 | F10: Male | G10: MG | H10: 542z | I10: 0 | J10: 2 | K10: 0 | L10: MG/00009 | M10: CourtTerme | N10: 201734 | O10: =AC10 -> 201734 | P10: =N10=O10 -> TRUE | Q10: Mensuelle | R10: 0 | S10: 0 | T10: Degressif | U10: F06B | V10: 01/03 | W10: =IF(VLOOKUP(V10,'reference classification'!$B$1:G14,6,FALSE)>90,1,0) -> 1 | X10: 0 | Y10: MG/00009 | Z10: 201734 | AA10: 120 | AB10: 201734 | AC10: 201734 | AD10: 0 | AE10: =AB10=AC10 -> TRUE
A11: 1132358 | B11: MG | C11: 41 | D11: 1964-10-17 00:00:00 | E11: 4101009 | F11: Male | G11: MG | H11: 324b | I11: 0 | J11: 2 | K11: 0 | L11: MG/00009 | M11: CourtTerme | N11: 100667.33 | O11: =AC11 -> 100667.33 | P11: =N11=O11 -> TRUE | Q11: Mensuelle | R11: 0 | S11: 21 | T11: Degressif | U11: F06B | V11: 01/03 | W11: =IF(VLOOKUP(V11,'reference classification'!$B$1:G15,6,FALSE)>90,1,0) -> 1 | X11: 0 | Y11: MG/00009 | Z11: 100667.33 | AA11: 120 | AB11: 100667.33 | AC11: 100667.33 | AD11: 0 | AE11: =AB11=AC11 -> TRUE
A12: 00005602399 | B12: MG | C12: 41 | D12: 1960-04-03 00:00:00 | E12: 3101001 | F12: Male | G12: MG | H12: 634z | I12: 0 | J12: 2 | K12: 0 | L12: MG/00009 | M12: CourtTerme | N12: 798464.67 | O12: =AC12 -> 798464.67 | P12: =N12=O12 -> TRUE | Q12: Mensuelle | R12: 0 | S12: 21 | T12: Degressif | U12: F06B | V12: 01/03 | W12: =IF(VLOOKUP(V12,'reference classification'!$B$1:G16,6,FALSE)>90,1,0) -> 1 | X12: 0 | Y12: MG/00009 | Z12: 798464.67 | AA12: 120 | AB12: 798464.67 | AC12: 798464.67 | AD12: 0 | AE12: =AB12=AC12 -> TRUE
A13: 00005763971 | B13: MG | C13: 41 | D13: 1990-08-11 00:00:00 | F13: Male | G13: MG | H13: 324e | I13: 0 | J13: 2 | K13: 0 | L13: MG/00009 | M13: CourtTerme | N13: 123538.28 | O13: =AC13 -> 123538.28 | P13: =N13=O13 -> TRUE | Q13: Mensuelle | R13: 0 | S13: 21 | T13: Degressif | U13: F06B | V13: 01/03 | W13: =IF(VLOOKUP(V13,'reference classification'!$B$1:G17,6,FALSE)>90,1,0) -> 1 | X13: 0 | Y13: MG/00009 | Z13: 123538.28 | AA13: 120 | AB13: 123538.28 | AC13: 123538.28 | AD13: 0 | AE13: =AB13=AC13 -> TRUE
A14: 00005801596 | B14: MG | C14: 41 | D14: 1986-03-21 00:00:00 | E14: 3101001 | F14: Male | G14: MG | H14: 634z | I14: 0 | J14: 1 | K14: 0 | L14: MG/00009 | M14: CourtTerme | N14: 840425 | O14: =AC14 -> 840425 | P14: =N14=O14 -> TRUE | Q14: Mensuelle | R14: 0 | S14: 0 | T14: Degressif | U14: F10B | V14: 01/03 | W14: =IF(VLOOKUP(V14,'reference classification'!$B$1:G18,6,FALSE)>90,1,0) -> 1 | X14: 0 | Y14: MG/00009 | Z14: 840425 | AA14: 118 | AB14: 840425 | AC14: 840425 | AD14: 0 | AE14: =AB14=AC14 -> TRUE
A15: 00490763826 | B15: MG | C15: 41 | D15: 1993-01-31 00:00:00 | E15: 3107010 | F15: Male | G15: MG | H15: 542b | I15: 0 | J15: 1 | K15: 0 | L15: MG/00009 | M15: CourtTerme | N15: 566630 | O15: =AC15 -> 566630 | P15: =N15=O15 -> TRUE | Q15: Mensuelle | R15: 0 | S15: 0 | T15: Degressif | U15: F10B | V15: 01/03 | W15: =IF(VLOOKUP(V15,'reference classification'!$B$1:G19,6,FALSE)>90,1,0) -> 1 | X15: 0 | Y15: MG/00009 | Z15: 566630 | AA15: 118 | AB15: 566630 | AC15: 566630 | AD15: 0 | AE15: =AB15=AC15 -> TRUE
A16: 00001102195088 | B16: MG | C16: 21 | D16: 1964-11-06 00:00:00 | F16: Male | G16: MG | H16: 381b | I16: 0 | J16: 1 | K16: 0 | L16: MG/00008 | M16: LongTerme | N16: 2 | O16: =AC16 -> 2 | P16: =N16=O16 -> TRUE | Q16: Mensuelle | R16: 0 | S16: 0 | T16: Constant | U16: F10C | V16: 01/03 | W16: =IF(VLOOKUP(V16,'reference classification'!$B$1:G20,6,FALSE)>90,1,0) -> 1 | X16: 0 | Y16: MG/00008 | Z16: 2 | AA16: 120 | AB16: 2 | AC16: 2 | AD16: 0 | AE16: =AB16=AC16 -> TRUE
A17: 00001102232790 | B17: MG | C17: 41 | D17: 1973-03-22 00:00:00 | F17: Male | G17: MG | H17: 563z | I17: 0 | J17: 1 | K17: 0 | L17: MG/00008 | M17: MoyenTerme | N17: 6931.81 | O17: =AC17 -> 6931.81 | P17: =N17=O17 -> TRUE | Q17: Mensuelle | R17: 0 | S17: 0 | T17: Constant | U17: F10C | V17: 01/03 | W17: =IF(VLOOKUP(V17,'reference classification'!$B$1:G21,6,FALSE)>90,1,0) -> 1 | X17: 0 | Y17: MG/00008 | Z17: 6931.81 | AA17: 120 | AB17: 6931.81 | AC17: 6931.81 | AD17: 0 | AE17: =AB17=AC17 -> TRUE
A18: 1912054442 | B18: MG | C18: 41 | D18: 1976-11-07 00:00:00 | E18: 1312110 | F18: Female | G18: MG | H18: 634z | I18: 0 | J18: 1 | K18: 0 | L18: MG/00008 | M18: LongTerme | N18: 2 | O18: =AC18 -> 2 | P18: =N18=O18 -> TRUE | Q18: Mensuelle | R18: 0 | S18: 0 | T18: Constant | U18: F10C | V18: 01/03 | W18: =IF(VLOOKUP(V18,'reference classification'!$B$1:G22,6,FALSE)>90,1,0) -> 1 | X18: 0 | Y18: MG/00008 | Z18: 2 | AA18: 120 | AB18: 2 | AC18: 2 | AD18: 0 | AE18: =AB18=AC18 -> TRUE
A19: 1912054686 | B19: MG | C19: 41 | D19: 1965-01-30 00:00:00 | E19: 1101001 | F19: Male | G19: MG | H19: 341g | I19: 0 | J19: 1 | K19: 0 | L19: MG/00008 | M19: LongTerme | N19: 2 | O19: =AC19 -> 2 | P19: =N19=O19 -> TRUE | Q19: Mensuelle | R19: 0 | S19: 0 | T19: Constant | U19: F10C | V19: 01/03 | W19: =IF(VLOOKUP(V19,'reference classification'!$B$1:G23,6,FALSE)>90,1,0) -> 1 | X19: 0 | Y19: MG/00008 | Z19: 2 | AA19: 120 | AB19: 2 | AC19: 2 | AD19: 0 | AE19: =AB19=AC19 -> TRUE
A20: 1912056862 | B20: BG | C20: 40 | D20: 1981-09-30 00:00:00 | F20: Male | G20: BG | H20: 563z | I20: 1 | J20: 1 | K20: 0 | L20: MG/00008 | M20: LongTerme | N20: 1 | O20: =AC20 -> 1 | P20: =N20=O20 -> TRUE | Q20: Mensuelle | R20: 0 | S20: 0 | T20: Constant | U20: F10C | V20: 01/03 | W20: =IF(VLOOKUP(V20,'reference classification'!$B$1:G24,6,FALSE)>90,1,0) -> 1 | X20: 0 | Y20: MG/00008 | Z20: 1 | AA20: 120 | AB20: 1 | AC20: 1 | AD20: 0 | AE20: =AB20=AC20 -> TRUE
A21: 1912057441 | B21: MG | C21: 41 | D21: 1997-09-06 00:00:00 | F21: Male | G21: MG | H21: 151b | I21: 0 | J21: 1 | K21: 0 | L21: MG/00008 | M21: CourtTerme | N21: 4207912.5 | O21: =AC21 -> 4207912.5 | P21: =N21=O21 -> TRUE | Q21: Mensuelle | R21: 0 | S21: 0 | T21: Constant | U21: F10C | V21: 01/03 | W21: =IF(VLOOKUP(V21,'reference classification'!$B$1:G25,6,FALSE)>90,1,0) -> 1 | X21: 0 | Y21: MG/00008 | Z21: 4207912.5 | AA21: 120 | AB21: 4207912.5 | AC21: 4207912.5 | AD21: 0 | AE21: =AB21=AC21 -> TRUE
A22: 1912058577 | B22: MG | C22: 41 | D22: 1988-02-10 00:00:00 | F22: Female | G22: MG | H22: 563z | I22: 0 | J22: 1 | K22: 0 | L22: MG/00008 | M22: LongTerme | N22: 2 | O22: =AC22 -> 2 | P22: =N22=O22 -> TRUE | Q22: Mensuelle | R22: 0 | S22: 0 | T22: Constant | U22: F10C | V22: 01/03 | W22: =IF(VLOOKUP(V22,'reference classification'!$B$1:G26,6,FALSE)>90,1,0) -> 1 | X22: 0 | Y22: MG/00008 | Z22: 2 | AA22: 120 | AB22: 2 | AC22: 2 | AD22: 0 | AE22: =AB22=AC22 -> TRUE
A23: 1912058714 | B23: MG | C23: 41 | D23: 1963-11-10 00:00:00 | F23: Male | G23: MG | H23: 324e | I23: 0 | J23: 2 | K23: 0 | L23: MG/00009 | M23: CourtTerme | N23: 275296.44 | O23: =AC23 -> 275296.44 | P23: =N23=O23 -> TRUE | Q23: Mensuelle | R23: 0 | S23: 21 | T23: Degressif | U23: F06B | V23: 01/03 | W23: =IF(VLOOKUP(V23,'reference classification'!$B$1:G27,6,FALSE)>90,1,0) -> 1 | X23: 0 | Y23: MG/00009 | Z23: 275296.44 | AA23: 120 | AB23: 275296.44 | AC23: 275296.44 | AD23: 0 | AE23: =AB23=AC23 -> TRUE
A24: 1912061193 | B24: MG | C24: 40 | D24: 1975-10-12 00:00:00 | F24: Male | G24: MG | H24: 311o | I24: 0 | J24: 2 | K24: 0 | L24: MG/00009 | M24: CourtTerme | N24: 384816.08 | O24: =AC24 -> 384816.08 | P24: =N24=O24 -> TRUE | Q24: Mensuelle | R24: 0 | S24: 0 | T24: Degressif | U24: F06B | V24: 01/03 | W24: =IF(VLOOKUP(V24,'reference classification'!$B$1:G28,6,FALSE)>90,1,0) -> 1 | X24: 0 | Y24: MG/00009 | Z24: 384816.08 | AA24: 120 | AB24: 384816.08 | AC24: 384816.08 | AD24: 0 | AE24: =AB24=AC24 -> TRUE
A25: 1912062313 | B25: MG | C25: 41 | D25: 1987-02-02 00:00:00 | F25: Male | G25: MG | H25: 219z | I25: 0 | J25: 2 | K25: 0 | L25: MG/00009 | M25: CourtTerme | N25: 8331.9 | O25: =AC25 -> 8331.9 | P25: =N25=O25 -> TRUE | Q25: Mensuelle | R25: 0 | S25: 0 | T25: Degressif | U25: F06B | V25: 01/03 | W25: =IF(VLOOKUP(V25,'reference classification'!$B$1:G29,6,FALSE)>90,1,0) -> 1 | X25: 0 | Y25: MG/00009 | Z25: 8331.9 | AA25: 120 | AB25: 8331.9 | AC25: 8331.9 | AD25: 0 | AE25: =AB25=AC25 -> TRUE
A26: 1912063908 | B26: MG | C26: 41 | D26: 1974-04-02 00:00:00 | E26: 2312032 | F26: Male | G26: MG | H26: 542z | I26: 0 | J26: 2 | K26: 0 | L26: MG/00009 | M26: CourtTerme | N26: 282914.03 | O26: =AC26 -> 282914.03 | P26: =N26=O26 -> TRUE | Q26: Mensuelle | R26: 0 | S26: 21 | T26: Degressif | U26: F06B | V26: 01/03 | W26: =IF(VLOOKUP(V26,'reference classification'!$B$1:G30,6,FALSE)>90,1,0) -> 1 | X26: 0 | Y26: MG/00009 | Z26: 282914.03 | AA26: 120 | AB26: 282914.03 | AC26: 282914.03 | AD26: 0 | AE26: =AB26=AC26 -> TRUE
A27: 1912068126 | B27: MG | C27: 41 | D27: 1984-07-26 00:00:00 | F27: Male | G27: MG | H27: 324z | I27: 0 | J27: 2 | K27: 0 | L27: MG/00009 | M27: CourtTerme | N27: 486294.36 | O27: =AC27 -> 486294.36 | P27: =N27=O27 -> TRUE | Q27: Mensuelle | R27: 0 | S27: 21 | T27: Degressif | U27: F06B | V27: 01/03 | W27: =IF(VLOOKUP(V27,'reference classification'!$B$1:G31,6,FALSE)>90,1,0) -> 1 | X27: 0 | Y27: MG/00009 | Z27: 486294.36 | AA27: 120 | AB27: 486294.36 | AC27: 486294.36 | AD27: 0 | AE27: =AB27=AC27 -> TRUE
A28: 1912069921 | B28: MG | C28: 41 | D28: 1970-02-13 00:00:00 | F28: Male | G28: MG | H28: 549z | I28: 0 | J28: 2 | K28: 0 | L28: MG/00009 | M28: CourtTerme | N28: 2285.33 | O28: =AC28 -> 2285.33 | P28: =N28=O28 -> TRUE | Q28: Mensuelle | R28: 0 | S28: 21 | T28: Degressif | U28: F06B | V28: 01/03 | W28: =IF(VLOOKUP(V28,'reference classification'!$B$1:G32,6,FALSE)>90,1,0) -> 1 | X28: 0 | Y28: MG/00009 | Z28: 2285.33 | AA28: 120 | AB28: 2285.33 | AC28: 2285.33 | AD28: 0 | AE28: =AB28=AC28 -> TRUE
A29: 1912070367 | B29: MG | C29: 41 | D29: 1965-10-31 00:00:00 | F29: Female | G29: MG | H29: 542z | I29: 0 | J29: 2 | K29: 0 | L29: MG/00009 | M29: CourtTerme | N29: 283884.86 | O29: =AC29 -> 283884.86 | P29: =N29=O29 -> TRUE | Q29: Mensuelle | R29: 0 | S29: 21 | T29: Degressif | U29: F06B | V29: 01/03 | W29: =IF(VLOOKUP(V29,'reference classification'!$B$1:G33,6,FALSE)>90,1,0) -> 1 | X29: 0 | Y29: MG/00009 | Z29: 283884.86 | AA29: 120 | AB29: 283884.86 | AC29: 283884.86 | AD29: 0 | AE29: =AB29=AC29 -> TRUE
A30: 1912070922 | B30: MG | C30: 41 | D30: 1991-08-09 00:00:00 | E30: 3101001 | F30: Male | G30: MG | H30: 634z | I30: 0 | J30: 2 | K30: 0 | L30: MG/00009 | M30: CourtTerme | N30: 183900.61 | O30: =AC30 -> 183900.61 | P30: =N30=O30 -> TRUE | Q30: Mensuelle | R30: 0 | S30: 0 | T30: Degressif | U30: F06B | V30: 01/03 | W30: =IF(VLOOKUP(V30,'reference classification'!$B$1:G34,6,FALSE)>90,1,0) -> 1 | X30: 0 | Y30: MG/00009 | Z30: 183900.61 | AA30: 120 | AB30: 183900.61 | AC30: 183900.61 | AD30: 0 | AE30: =AB30=AC30 -> TRUE
A31: 1912072482 | B31: MG | C31: 41 | D31: 1974-05-03 00:00:00 | F31: Male | G31: MG | H31: 542z | I31: 0 | J31: 2 | K31: 0 | L31: MG/00009 | M31: CourtTerme | N31: 210306.82 | O31: =AC31 -> 210306.82 | P31: =N31=O31 -> TRUE | Q31: Mensuelle | R31: 0 | S31: 21 | T31: Degressif | U31: F06B | V31: 01/03 | W31: =IF(VLOOKUP(V31,'reference classification'!$B$1:G35,6,FALSE)>90,1,0) -> 1 | X31: 0 | Y31: MG/00009 | Z31: 210306.82 | AA31: 120 | AB31: 210306.82 | AC31: 210306.82 | AD31: 0 | AE31: =AB31=AC31 -> TRUE
A32: 1912075905 | B32: MG | C32: 41 | D32: 1971-02-28 00:00:00 | F32: Male | G32: MG | H32: 542z | I32: 0 | J32: 2 | K32: 0 | L32: MG/00009 | M32: CourtTerme | N32: 102491.93 | O32: =AC32 -> 102491.93 | P32: =N32=O32 -> TRUE | Q32: Mensuelle | R32: 0 | S32: 21 | T32: Degressif | U32: F06B | V32: 01/03 | W32: =IF(VLOOKUP(V32,'reference classification'!$B$1:G36,6,FALSE)>90,1,0) -> 1 | X32: 0 | Y32: MG/00009 | Z32: 102491.93 | AA32: 120 | AB32: 102491.93 | AC32: 102491.93 | AD32: 0 | AE32: =AB32=AC32 -> TRUE
A33: 1912076141 | B33: MG | C33: 41 | D33: 2030-05-07 00:00:00 | F33: Female | G33: MG | H33: 563z | I33: 0 | J33: 2 | K33: 0 | L33: MG/00009 | M33: CourtTerme | N33: 1023115 | O33: =AC33 -> 1023115 | P33: =N33=O33 -> TRUE | Q33: Mensuelle | R33: 0 | S33: 21 | T33: Degressif | U33: F06B | V33: 01/03 | W33: =IF(VLOOKUP(V33,'reference classification'!$B$1:G37,6,FALSE)>90,1,0) -> 1 | X33: 0 | Y33: MG/00009 | Z33: 1023115 | AA33: 120 | AB33: 1023115 | AC33: 1023115 | AD33: 0 | AE33: =AB33=AC33 -> TRUE
A34: 1912076473 | B34: MG | C34: 41 | D34: 1981-10-27 00:00:00 | F34: Female | G34: MG | H34: 219z | I34: 0 | J34: 2 | K34: 0 | L34: MG/00009 | M34: CourtTerme | N34: 108130.5 | O34: =AC34 -> 108130.5 | P34: =N34=O34 -> TRUE | Q34: Mensuelle | R34: 0 | S34: 0 | T34: Degressif | U34: F06B | V34: 01/03 | W34: =IF(VLOOKUP(V34,'reference classification'!$B$1:G38,6,FALSE)>90,1,0) -> 1 | X34: 0 | Y34: MG/00009 | Z34: 108130.5 | AA34: 120 | AB34: 108130.5 | AC34: 108130.5 | AD34: 0 | AE34: =AB34=AC34 -> TRUE
A35: 1912078057 | B35: MG | C35: 41 | D35: 1985-10-02 00:00:00 | E35: 2105010 | F35: Male | G35: MG | H35: 521z | I35: 0 | J35: 1 | K35: 0 | L35: MG/00009 | M35: CourtTerme | N35: 320329.31 | O35: =AC35 -> 320329.31 | P35: =N35=O35 -> TRUE | Q35: Mensuelle | R35: 0 | S35: 0 | T35: Degressif | U35: F10B | V35: 01/03 | W35: =IF(VLOOKUP(V35,'reference classification'!$B$1:G39,6,FALSE)>90,1,0) -> 1 | X35: 0 | Y35: MG/00009 | Z35: 320329.31 | AA35: 118 | AB35: 320329.31 | AC35: 320329.31 | AD35: 0 | AE35: =AB35=AC35 -> TRUE
A36: 1912079810 | B36: MG | C36: 41 | D36: 1985-12-12 00:00:00 | E36: 1106352 | F36: Male | G36: MG | H36: 382o | I36: 0 | J36: 2 | K36: 0 | L36: MG/00009 | M36: CourtTerme | N36: 150962.88 | O36: =AC36 -> 150962.88 | P36: =N36=O36 -> TRUE | Q36: Mensuelle | R36: 0 | S36: 0 | T36: Degressif | U36: F06B | V36: 01/03 | W36: =IF(VLOOKUP(V36,'reference classification'!$B$1:G40,6,FALSE)>90,1,0) -> 1 | X36: 0 | Y36: MG/00009 | Z36: 150962.88 | AA36: 120 | AB36: 150962.88 | AC36: 150962.88 | AD36: 0 | AE36: =AB36=AC36 -> TRUE
A37: 1912082542 | B37: MG | C37: 41 | D37: 1993-08-25 00:00:00 | F37: Female | G37: MG | H37: 721c | I37: 0 | J37: 2 | K37: 0 | L37: MG/00009 | M37: CourtTerme | N37: 1506608.4 | O37: =AC37 -> 1506608.4 | P37: =N37=O37 -> TRUE | Q37: Mensuelle | R37: 0 | S37: 21 | T37: Degressif | U37: F06B | V37: 01/03 | W37: =IF(VLOOKUP(V37,'reference classification'!$B$1:G41,6,FALSE)>90,1,0) -> 1 | X37: 0 | Y37: MG/00009 | Z37: 1506608.4 | AA37: 120 | AB37: 1506608.4 | AC37: 1506608.4 | AD37: 0 | AE37: =AB37=AC37 -> TRUE
A38: 1912083051 | B38: MG | C38: 41 | D38: 1992-10-31 00:00:00 | E38: 1101004 | F38: Male | G38: MG | H38: 542z | I38: 0 | J38: 1 | K38: 0 | L38: MG/00009 | M38: CourtTerme | N38: 968345.75 | O38: =AC38 -> 968345.75 | P38: =N38=O38 -> TRUE | Q38: Mensuelle | R38: 0 | S38: 0 | T38: Degressif | U38: F10B | V38: 01/03 | W38: =IF(VLOOKUP(V38,'reference classification'!$B$1:G42,6,FALSE)>90,1,0) -> 1 | X38: 0 | Y38: MG/00009 | Z38: 968345.75 | AA38: 118 | AB38: 968345.75 | AC38: 968345.75 | AD38: 0 | AE38: =AB38=AC38 -> TRUE
A39: 1912088067 | B39: MG | C39: 41 | D39: 1987-07-15 00:00:00 | F39: Male | G39: MG | H39: 712e | I39: 0 | J39: 2 | K39: 0 | L39: MG/00009 | M39: CourtTerme | N39: 573794.23 | O39: =AC39 -> 573794.23 | P39: =N39=O39 -> TRUE | Q39: Mensuelle | R39: 0 | S39: 21 | T39: Degressif | U39: F06B | V39: 01/03 | W39: =IF(VLOOKUP(V39,'reference classification'!$B$1:G43,6,FALSE)>90,1,0) -> 1 | X39: 0 | Y39: MG/00009 | Z39: 573794.23 | AA39: 120 | AB39: 573794.23 | AC39: 573794.23 | AD39: 0 | AE39: =AB39=AC39 -> TRUE
A40: 1912088402 | B40: MG | C40: 41 | D40: 1955-02-13 00:00:00 | F40: Female | G40: MG | H40: 521z | I40: 0 | J40: 2 | K40: 0 | L40: MG/00009 | M40: CourtTerme | N40: 32742.96 | O40: =AC40 -> 32742.96 | P40: =N40=O40 -> TRUE | Q40: Mensuelle | R40: 0 | S40: 0 | T40: Degressif | U40: F06B | V40: 01/03 | W40: =IF(VLOOKUP(V40,'reference classification'!$B$1:G44,6,FALSE)>90,1,0) -> 1 | X40: 0 | Y40: MG/00009 | Z40: 32742.96 | AA40: 120 | AB40: 32742.96 | AC40: 32742.96 | AD40: 0 | AE40: =AB40=AC40 -> TRUE
...

Sheet reference classification
A1: PK_ | B1: CODE_ | C1: DEFINITION_ | D1: DESCRIPTION_ | E1: IDENTIFIANT_ | F1: MAXNBJIMPAYE_ | G1: MINNBJIMPAYE_ | H1: ORDER_ | I1: STATUT_ | J1: TYPEINSTITUTIONCODE_ | K1: TYPEINSTITUTIONPK_ | L1: UDATE_ | M1: VERSIONNUM_
A2: 1 | B2: 01/03 | C2: 91 ET PLUS SI CREDIT AMORTISSABLE / 61 ET PLUS POUR L?ESCPTE DE PAPIER COMMERCIAL | D2: DOUTEUSE | E2: 3 | F2: 99999999 | G2: 91 | H2: 3 | I2: Validee | J2: 1 | K2: 14 | L2: 2023-03-22 18:49:07 | M2: 2
A3: 2 | B3: 01/01 | C3: 0 a 90 jours d'impayes | D3: SAINE | E3: 1 | F3: 90 | G3: 0 | H3: 1 | I3: Validee | J3: 1 | K3: 14 | L3: 2023-03-22 18:46:41 | M3: 1
A4: 3 | B4: 01/02 | C4: appreciation de chaque etablissement | D4: IMMOBILISEE | E4: 2 | F4: 99999999 | G4: 0 | H4: 2 | I4: Validee | J4: 1 | K4: 14 | L4: 2023-03-22 18:49:14 | M4: 3
A5: 4 | B5: 02/01 | C5: 0 a 30 jours d'impayes | D5: SAINE | E5: 1 | F5: 30 | G5: 0 | H5: 4 | I5: Validee | J5: 2 | K5: 8 | L5: 2023-03-22 18:46:12 | M5: 1
A6: 5 | B6: 02/02 | C6: 31 jours d'impayes et plus | D6: EN SOUFFRANCE | E6: 2 | F6: 9999999 | G6: 31 | H6: 5 | I6: Validee | J6: 2 | K6: 8 | L6: 2023-03-22 18:50:31 | M6: 3
